Workbook

Sheet Task
B2: Retention Analyst - Task
A4: 1 | B4: Extract all unique Games, Creators & Providers with their IDs. List them in separate sheet.
A6: 2 | B6: Make a pivot table in separate sheet, listing the Creators with most players (including separation by Month, By currenty)
B7: use "First Bet" as a month
A9: 3 | B9: Prepare a dashboard in sepate sheet, showing most profitable provider (GGR) for September
B10: use "First Bet" as a month
A12: 4 | B12: Analyse the data find some useful metrics which could be helpful in the future of the decision making
B13: your decision
B17: (If some of the Column titles are not familiar for you, please re-search for them in internet related to online casino industry)
B19: Please, create a new Goole document ( copy the data and send it back)

Sheet Data
A1: Game ID | B1: Game | C1: Provider | D1: Provider ID | E1: Creator | F1: Creator ID | G1: Currency | H1: RM Bets | I1: RM Win | J1: GGR | K1: Bonus Bets | L1: Bonus Win | M1: Bonus Revenue | N1: Total Bets | O1: Total Win | P1: Payout | Q1: No. of Players | R1: First Bet | S1: Last Bet
A2: 421 | B2: All Fruits HD | C2: BetConstruct | D2: 2 | E2: Worldmatch | F2: 39 | G2: MYR | H2: 25 | I2: 0 | J2: 25 | K2: 0 | L2: 0 | M2: 0 | N2: 25 | O2: 0 | P2: 25 | Q2: 1 | R2: 2022-09-08T01:11:22+00:00 | S2: 2022-09-08T01:11:22+00:00
A3: 697 | B3: Stoned Joker 5 | C3: BetConstruct | D3: 2 | E3: Fugaso | F3: 120 | G3: MYR | H3: 1568 | I3: 0 | J3: 1568 | K3: 0 | L3: 0 | M3: 0 | N3: 1568 | O3: 0 | P3: 1568 | Q3: 1 | R3: 2022-09-04T12:54:01+00:00 | S3: 2022-09-04T12:54:31+00:00
A4: 1863 | B4: HotHoney 22 VIP | C4: BetConstruct | D4: 2 | E4: MrSlotty | F4: 45 | G4: MYR | H4: 125 | I4: 0 | J4: 125 | K4: 0 | L4: 0 | M4: 0 | N4: 125 | O4: 0 | P4: 125 | Q4: 1 | R4: 2022-09-07T11:34:38+00:00 | S4: 2022-09-07T11:34:38+00:00
A5: 1871 | B5: Dolphins Gold | C5: BetConstruct | D5: 2 | E5: MrSlotty | F5: 45 | G5: MYR | H5: 20 | I5: 0 | J5: 20 | K5: 0 | L5: 0 | M5: 0 | N5: 20 | O5: 0 | P5: 20 | Q5: 1 | R5: 2022-08-17T18:44:45+00:00 | S5: 2022-07-17T18:44:58+00:00
A6: 1908 | B6: Golfn Monkeys | C6: BetConstruct | D6: 2 | E6: Multislot | F6: 41 | G6: MYR | H6: 40 | I6: 0 | J6: 40 | K6: 0 | L6: 0 | M6: 0 | N6: 40 | O6: 0 | P6: 40 | Q6: 1 | R6: 2022-09-03T19:18:45+00:00 | S6: 2022-09-03T19:19:08+00:00
A7: 2029 | B7: DragonTiger | C7: BetConstruct | D7: 2 | E7: AG Gaming | F7: 21 | G7: MYR | H7: 20000 | I7: 0 | J7: 20000 | K7: 0 | L7: 0 | M7: 0 | N7: 20000 | O7: 0 | P7: 20000 | Q7: 1 | R7: 2022-08-24T19:03:23+00:00 | S7: 2022-07-24T19:03:23+00:00
A8: 2735 | B8: Roulette B | C8: BetConstruct | D8: 2 | E8: Betconstruct | F8: 34 | G8: MYR | H8: 5250 | I8: 0 | J8: 5250 | K8: 0 | L8: 0 | M8: 0 | N8: 5250 | O8: 0 | P8: 5250 | Q8: 1 | R8: 2022-08-29T09:46:12+00:00 | S8: 2022-08-29T09:49:10+00:00
A9: 2750 | B9: Roulette | C9: BetConstruct | D9: 2 | E9: Vision Casino | F9: 161 | G9: MYR | H9: 450 | I9: 0 | J9: 450 | K9: 0 | L9: 0 | M9: 0 | N9: 450 | O9: 0 | P9: 450 | Q9: 1 | R9: 2022-08-22T05:09:33+00:00 | S9: 2022-08-22T05:09:33+00:00
A10: 2767 | B10: Aztec Gems Deluxe™ | C10: BetConstruct | D10: 2 | E10: Pragmatic Play | F10: 24 | G10: MYR | H10: 72 | I10: 0 | J10: 72 | K10: 0 | L10: 0 | M10: 0 | N10: 72 | O10: 0 | P10: 72 | Q10: 1 | R10: 2022-08-07T04:42:22+00:00 | S10: 2022-07-07T04:42:25+00:00
A11: 2879 | B11: Return of the Dead™ | C11: BetConstruct | D11: 2 | E11: Pragmatic Play | F11: 24 | G11: MYR | H11: 10000 | I11: 0 | J11: 10000 | K11: 0 | L11: 0 | M11: 0 | N11: 10000 | O11: 0 | P11: 10000 | Q11: 1 | R11: 2022-08-17T10:12:44+00:00 | S11: 2022-07-17T10:13:18+00:00
A12: 3127 | B12: Aztec Temple | C12: Slotegrator | D12: 6 | E12: Platipus | F12: 249 | G12: MYR | H12: 300 | I12: 0 | J12: 300 | K12: 0 | L12: 0 | M12: 0 | N12: 300 | O12: 0 | P12: 300 | Q12: 1 | R12: 2022-08-20T17:37:57+00:00 | S12: 2022-07-20T17:38:03+00:00
A13: 3174 | B13: Gladiator | C13: Slotegrator | D13: 6 | E13: Betsoft | F13: 55 | G13: MYR | H13: 50 | I13: 0 | J13: 50 | K13: 0 | L13: 0 | M13: 0 | N13: 50 | O13: 0 | P13: 50 | Q13: 1 | R13: 2022-08-29T18:44:47+00:00 | S13: 2022-08-29T18:44:56+00:00
... A470: 20758 | B470: Amazing Link™ Bounty | C470: Mic | D470: 1 | E470: SpinPlay Games | F470: 156 | G470: MYR | H470: 10800 | I470: 2930 | J470: 7870 | K470: 0 | L470: 0 | M470: 0 | N470: 10800 | O470: 2930 | P470: 7870 | Q470: 1 | R470: 2022-08-16T07:28:12+00:00 | S470: 2022-08-16T07:33:44+00:00
A471: 12868 | B471: 888 | C471: Slotegrator | D471: 6 | E471: Spadegaming | F471: 138 | G471: SGD | H471: 459843 | I471: 429760 | J471: 30083 | K471: 13417 | L471: 16300 | M471: -2883 | N471: 473260 | O471: 446060 | P471: 27200 | Q471: 25 | R471: 2022-07-02T14:25:09+00:00 | S471: 2022-09-28T01:43:01+00:00
A472: 429 | B472: Legend of Ra | C472: BetConstruct | D472: 2 | E472: Evoplay Entertainment | F472: 116 | G472: SGD | H472: 220 | I472: 60 | J472: 160 | K472: 0 | L472: 0 | M472: 0 | N472: 220 | O472: 60 | P472: 160 | Q472: 1 | R472: 2022-08-23T03:15:18+00:00 | S472: 2022-07-23T03:16:15+00:00
A473: 5814 | B473: Book Of Souls | C473: Mic | D473: 1 | E473: Spearhead Studios | F473: 154 | G473: SGD | H473: 4400 | I473: 1200 | J473: 3200 | K473: 0 | L473: 0 | M473: 0 | N473: 4400 | O473: 1200 | P473: 3200 | Q473: 1 | R473: 2022-09-19T03:54:26+00:00 | S473: 2022-09-19T03:59:00+00:00
A474: 998 | B474: Five Star | C474: BetConstruct | D474: 2 | E474: Red Tiger | F474: 51 | G474: SGD | H474: 0 | I474: 0 | J474: 0 | K474: 3434 | L474: 937 | M474: 2497 | N474: 3434 | O474: 937 | P474: 2497 | Q474: 1 | R474: 2022-09-02T16:46:43+00:00 | S474: 2022-09-02T16:49:52+00:00
A475: 3436 | B475: Sevens High Mobile | C475: Slotegrator | D475: 6 | E475: Quickspin | F475: 83 | G475: MYR | H475: 2775 | I475: 759 | J475: 2016 | K475: 0 | L475: 0 | M475: 0 | N475: 2775 | O475: 759 | P475: 2016 | Q475: 1 | R475: 2022-09-02T04:10:52+00:00 | S475: 2022-09-02T04:14:32+00:00
A476: 16032 | B476: Star Pirates Code™ | C476: BetConstruct | D476: 2 | E476: Pragmatic Play | F476: 24 | G476: SGD | H476: 2550 | I476: 698 | J476: 1852 | K476: 0 | L476: 0 | M476: 0 | N476: 2550 | O476: 698 | P476: 1852 | Q476: 2 | R476: 2022-08-04T07:08:44+00:00 | S476: 2022-08-25T13:02:28+00:00
A477: 17286 | B477: Tasty Treats | C477: Mic | D477: 1 | E477: Hacksaw Gamingsgsdgds | F477: 165 | G477: MYR | H477: 4480 | I477: 1228 | J477: 3252 | K477: 0 | L477: 0 | M477: 0 | N477: 4480 | O477: 1228 | P477: 3252 | Q477: 1 | R477: 2022-08-08T19:39:02+00:00 | S477: 2022-08-08T19:44:17+00:00
A478: 982 | B478: Chinese Wilds | C478: BetConstruct | D478: 2 | E478: Red Tiger | F478: 51 | G478: SGD | H478: 1364 | I478: 374 | J478: 990 | K478: 0 | L478: 0 | M478: 0 | N478: 1364 | O478: 374 | P478: 990 | Q478: 4 | R478: 2022-08-10T22:59:29+00:00 | S478: 2022-09-15T07:54:48+00:00
A479: 13260 | B479: Gems Bonanza Mobile | C479: Slotegrator | D479: 6 | E479: Pragmatic Play | F479: 24 | G479: MYR | H479: 160 | I479: 44 | J479: 116 | K479: 0 | L479: 0 | M479: 0 | N479: 160 | O479: 44 | P479: 116 | Q479: 1 | R479: 2022-09-28T12:29:54+00:00 | S479: 2022-09-28T12:30:26+00:00
A480: 13651 | B480: Fast & Sexy | C480: BetConstruct | D480: 2 | E480: Genesis | F480: 27 | G480: SGD | H480: 1754 | I480: 483 | J480: 1271 | K480: 0 | L480: 0 | M480: 0 | N480: 1754 | O480: 483 | P480: 1271 | Q480: 1 | R480: 2022-09-25T09:30:45+00:00 | S480: 2022-09-25T09:31:31+00:00
A481: 6436 | B481: Fortunium | C481: Mic | D481: 1 | E481: StormCraft | F481: 105 | G481: MYR | H481: 9450 | I481: 2610 | J481: 6840 | K481: 0 | L481: 0 | M481: 0 | N481: 9450 | O481: 2610 | P481: 6840 | Q481: 1 | R481: 2022-08-30T18:52:16+00:00 | S481: 2022-07-30T18:53:35+00:00
A482: 1391 | B482: Emerald Diamond | C482: BetConstruct | D482: 2 | E482: Red Tiger | F482: 51 | G482: SGD | H482: 46937 | I482: 12963 | J482: 33974 | K482: 0 | L482: 0 | M482: 0 | N482: 46937 | O482: 12963 | P482: 33974 | Q482: 2 | R482: 2022-09-05T03:54:19+00:00 | S482: 2022-09-29T01:02:01+00:00
A483: 5230 | B483: Money From Mars | C483: Mic | D483: 1 | E483: Ainsworth Games | F483: 80 | G483: MYR | H483: 6800 | I483: 1880 | J483: 4920 | K483: 0 | L483: 0 | M483: 0 | N483: 6800 | O483: 1880 | P483: 4920 | Q483: 1 | R483: 2022-08-29T16:10:00+00:00 | S483: 2022-08-29T16:12:00+00:00
... A1083: 19593 | B1083: Divine Fire | C1083: BetConstruct | D1083: 2 | E1083: Gamomat | F1083: 164 | G1083: MYR | H1083: 10920 | I1083: 6020 | J1083: 4900 | K1083: 0 | L1083: 0 | M1083: 0 | N1083: 10920 | O1083: 6020 | P1083: 4900 | Q1083: 1 | R1083: 2022-09-03T05:17:35+00:00 | S1083: 2022-09-03T05:21:11+00:00
A1084: 12868 | B1084: 888 | C1084: Slotegrator | D1084: 6 | E1084: Spadegaming | F1084: 138 | G1084: MYR | H1084: 580 | I1084: 320 | J1084: 260 | K1084: 0 | L1084: 0 | M1084: 0 | N1084: 580 | O1084: 320 | P1084: 260 | Q1084: 1 | R1084: 2022-09-20T04:24:09+00:00 | S1084: 2022-09-20T04:25:17+00:00
A1085: 5642 | B1085: Barbarians Gold | C1085: Mic | D1085: 1 | E1085: 1x2 Gaming | F1085: 18 | G1085: MYR | H1085: 8940 | I1085: 4935 | J1085: 4005 | K1085: 0 | L1085: 0 | M1085: 0 | N1085: 8940 | O1085: 4935 | P1085: 4005 | Q1085: 1 | R1085: 2022-09-27T12:10:16+00:00 | S1085: 2022-09-27T12:18:01+00:00
A1086: 17830 | B1086: Book of Amaterasu | C1086: Slotegrator | D1086: 6 | E1086: Mascot | F1086: 305 | G1086: MYR | H1086: 4600 | I1086: 2540 | J1086: 2060 | K1086: 0 | L1086: 0 | M1086: 0 | N1086: 4600 | O1086: 2540 | P1086: 2060 | Q1086: 1 | R1086: 2022-08-05T07:31:30+00:00 | S1086: 2022-08-05T07:32:54+00:00
A1087: 13278 | B1087: The Dog House Mobile | C1087: Slotegrator | D1087: 6 | E1087: Pragmatic Play | F1087: 24 | G1087: SGD | H1087: 75380 | I1087: 118486 | J1087: -43106 | K1087: 3340 | L1087: 6802 | M1087: -3462 | N1087: 78720 | O1087: 125288 | P1087: -46568 | Q1087: 11 | R1087: 2022-09-28T15:11:56+00:00 | S1087: 2022-09-30T17:41:25+00:00
A1088: 3336 | B1088: Pirate’s Charm | C1088: Slotegrator | D1088: 6 | E1088: Quickspin | F1088: 83 | G1088: MYR | H1088: 47040 | I1088: 25980 | J1088: 21060 | K1088: 0 | L1088: 0 | M1088: 0 | N1088: 47040 | O1088: 25980 | P1088: 21060 | Q1088: 2 | R1088: 2022-08-01T07:21:49+00:00 | S1088: 2022-09-30T14:17:43+00:00
A1089: 987 | B1089: Divine Ways | C1089: BetConstruct | D1089: 2 | E1089: Red Tiger | F1089: 51 | G1089: SGD | H1089: 16935 | I1089: 9355 | J1089: 7580 | K1089: 0 | L1089: 0 | M1089: 0 | N1089: 16935 | O1089: 9355 | P1089: 7580 | Q1089: 7 | R1089: 2022-08-08T15:20:00+00:00 | S1089: 2022-09-17T16:16:29+00:00
A1090: 12744 | B1090: El Paso Gunfight xNudge | C1090: BetConstruct | D1090: 2 | E1090: No LimitCity | F1090: 266 | G1090: MYR | H1090: 94250 | I1090: 52135 | J1090: 42115 | K1090: 0 | L1090: 0 | M1090: 0 | N1090: 94250 | O1090: 52135 | P1090: 42115 | Q1090: 5 | R1090: 2022-08-12T08:35:37+00:00 | S1090: 2022-08-31T00:16:22+00:00
A1091: 6016 | B1091: Christmas Megaways | C1091: Mic | D1091: 1 | E1091: 1x2 Gaming | F1091: 18 | G1091: SGD | H1091: 8960 | I1091: 4958 | J1091: 4002 | K1091: 0 | L1091: 0 | M1091: 0 | N1091: 8960 | O1091: 4958 | P1091: 4002 | Q1091: 1 | R1091: 2022-08-31T06:36:34+00:00 | S1091: 2022-07-31T06:47:32+00:00
A1092: 16074 | B1092: Wild Wet Win | C1092: Slotegrator | D1092: 6 | E1092: Spadegaming | F1092: 138 | G1092: SGD | H1092: 75204 | I1092: 47900 | J1092: 27304 | K1092: 22676 | L1092: 22595 | M1092: 81 | N1092: 97880 | O1092: 70495 | P1092: 27385 | Q1092: 11 | R1092: 2022-09-02T01:02:38+00:00 | S1092: 2022-09-30T23:59:30+00:00
A1093: 20867 | B1093: Greedy Wolf™ | C1093: BetConstruct | D1093: 2 | E1093: Pragmatic Play | F1093: 24 | G1093: MYR | H1093: 210449 | I1093: 117165 | J1093: 93284 | K1093: 1221 | L1093: 354 | M1093: 867 | N1093: 211670 | O1093: 117519 | P1093: 94151 | Q1093: 5 | R1093: 2022-08-06T20:05:35+00:00 | S1093: 2022-09-14T13:51:48+00:00
A1094: 11598 | B1094: Book Of Clovers | C1094: Slotegrator | D1094: 6 | E1094: SpinomenalFalse | F1094: 56 | G1094: SGD | H1094: 73857 | I1094: 37837 | J1094: 36020 | K1094: 2453 | L1094: 453 | M1094: 2000 | N1094: 76310 | O1094: 38290 | P1094: 38020 | Q1094: 15 | R1094: 2022-08-22T20:37:43+00:00 | S1094: 2022-09-28T11:56:18+00:00
A1095: 12918 | B1095: Pirate King | C1095: Slotegrator | D1095: 6 | E1095: Spadegaming | F1095: 138 | G1095: SGD | H1095: 73548 | I1095: 56250 | J1095: 17298 | K1095: 0 | L1095: 0 | M1095: 0 | N1095: 73548 | O1095: 56250 | P1095: 17298 | Q1095: 2 | R1095: 2022-09-10T16:59:39+00:00 | S1095: 2022-09-20T06:53:02+00:00
...

Sheet Unique Games per P and C
A1: Game | B1: Game ID | C1: Provider | D1: Provider ID | E1: Creator | F1: Creator ID
A2: All Fruits HD | B2: 421 | C2: BetConstruct | D2: 2 | E2: Worldmatch | F2: 39
A3: Stoned Joker 5 | B3: 697 | C3: BetConstruct | D3: 2 | E3: Fugaso | F3: 120
A4: HotHoney 22 VIP | B4: 1863 | C4: BetConstruct | D4: 2 | E4: MrSlotty | F4: 45
A5: Dolphins Gold | B5: 1871 | C5: BetConstruct | D5: 2 | E5: MrSlotty | F5: 45
A6: Golfn Monkeys | B6: 1908 | C6: BetConstruct | D6: 2 | E6: Multislot | F6: 41
A7: DragonTiger | B7: 2029 | C7: BetConstruct | D7: 2 | E7: AG Gaming | F7: 21
A8: Roulette B | B8: 2735 | C8: BetConstruct | D8: 2 | E8: Betconstruct | F8: 34
A9: Roulette | B9: 2750 | C9: BetConstruct | D9: 2 | E9: Vision Casino | F9: 161
A10: Aztec Gems Deluxe™ | B10: 2767 | C10: BetConstruct | D10: 2 | E10: Pragmatic Play | F10: 24
A11: Return of the Dead™ | B11: 2879 | C11: BetConstruct | D11: 2 | E11: Pragmatic Play | F11: 24
A12: Aztec Temple | B12: 3127 | C12: Slotegrator | D12: 6 | E12: Platipus | F12: 249
A13: Gladiator | B13: 3174 | C13: Slotegrator | D13: 6 | E13: Betsoft | F13: 55
... A464: Amazing Link™ Bounty | B464: 20758 | C464: Mic | D464: 1 | E464: SpinPlay Games | F464: 156
A465: 888 | B465: 12868 | C465: Slotegrator | D465: 6 | E465: Spadegaming | F465: 138
A466: Legend of Ra | B466: 429 | C466: BetConstruct | D466: 2 | E466: Evoplay Entertainment | F466: 116
A467: Book Of Souls | B467: 5814 | C467: Mic | D467: 1 | E467: Spearhead Studios | F467: 154
A468: Five Star | B468: 998 | C468: BetConstruct | D468: 2 | E468: Red Tiger | F468: 51
A469: Sevens High Mobile | B469: 3436 | C469: Slotegrator | D469: 6 | E469: Quickspin | F469: 83
A470: Star Pirates Code™ | B470: 16032 | C470: BetConstruct | D470: 2 | E470: Pragmatic Play | F470: 24
A471: Tasty Treats | B471: 17286 | C471: Mic | D471: 1 | E471: Hacksaw Gamingsgsdgds | F471: 165
A472: Chinese Wilds | B472: 982 | C472: BetConstruct | D472: 2 | E472: Red Tiger | F472: 51
A473: Gems Bonanza Mobile | B473: 13260 | C473: Slotegrator | D473: 6 | E473: Pragmatic Play | F473: 24
A474: Fast & Sexy | B474: 13651 | C474: BetConstruct | D474: 2 | E474: Genesis | F474: 27
A475: Fortunium | B475: 6436 | C475: Mic | D475: 1 | E475: StormCraft | F475: 105
A476: Emerald Diamond | B476: 1391 | C476: BetConstruct | D476: 2 | E476: Red Tiger | F476: 51
A477: Money From Mars | B477: 5230 | C477: Mic | D477: 1 | E477: Ainsworth Games | F477: 80
... A2914: Fruit Bat Crazy | B2914: 3653 | C2914: Slotegrator | D2914: 6 | E2914: Betsoft | F2914: 55
A2915: 777 | B2915: 18835 | C2915: Slotegrator | D2915: 6 | E2915: SmartSoft | F2915: 312
A2916: Reel Gems | B2916: 7487 | C2916: Mic | D2916: 1 | E2916: Microgaming | F2916: 38
A2917: Pirate's Plenty | B2917: 1019 | C2917: BetConstruct | D2917: 2 | E2917: Red Tiger | F2917: 51
A2918: Double Dragons | B2918: 4173 | C2918: Slotegrator | D2918: 6 | E2918: Yggdrasil | F2918: 257
A2919: Crystal Caverns Megaways™ | B2919: 16597 | C2919: BetConstruct | D2919: 2 | E2919: Pragmatic Play | F2919: 24
A2920: Wild Depths | B2920: 17455 | C2920: Slotegrator | D2920: 6 | E2920: Pragmatic Play | F2920: 24
A2921: Golden Dollars | B2921: 6579 | C2921: Mic | D2921: 1 | E2921: Ainsworth Games | F2921: 80
A2922: 88 Golden 88 | B2922: 10520 | C2922: Slotegrator | D2922: 6 | E2922: Belatra Games | F2922: 271
A2923: Speed Baccarat L | B2923: 4969 | C2923: BetConstruct | D2923: 2 | E2923: Betconstruct | F2923: 34
A2924: Hot Muchacho | B2924: 17918 | C2924: BetConstruct | D2924: 2 | E2924: Popok Gaming | F2924: 277
A2925: Bounty Gold™ | B2925: 16235 | C2925: BetConstruct | D2925: 2 | E2925: Pragmatic Play | F2925: 24
A2926: Trail Blazer | B2926: 10955 | C2926: BetConstruct | D2926: 2 | E2926: Relax Gaming | F2926: 252
...

Sheet Unique Games
A1: Game | B1: Game ID
A2: 777 | B2: 18835
A3: 888 | B3: 12868
A4: #Alice and the Mad Respin Party | B4: 15772
A5: #Alice in the Wild | B5: 15747
A6: #LuxuryLife | B6: 13055
A7: $LOT OF MONEY | B7: 9012
A8: 1 2 3 Boom!™ | B8: 11022
A9: 1 In A Million | B9: 19252
A10: 1 Reel Demi Gods IV | B10: 21121
A11: 100 Joker Staxx | B11: 5350
A12: 100 Joker Staxx | B12: 5351
A13: 1000x Busta | B13: 11021
A14: 1001 Spins | B14: 12496
A15: 12 Trojan Mysteries | B15: 13586
... A3279: Zulu Gold | B3279: 14865

Sheet Unique Providers
A1: Provider | B1: Provider ID
A2: BetConstruct | B2: 2
A3: Mic | B3: 1
A4: Slotegrator | B4: 6

Sheet Unique Creators
A1: Creator | B1: Creator ID
A2: 1x2 Gaming | B2: 18
A3: 2By2 | B3: 78
A4: AG Gaming | B4: 21
A5: Ainsworth Games | B5: 80
A6: Alchemy Gaming | B6: 148
A7: All41 Studios | B7: 110
A8: Amatic | B8: 7
A9: ASG | B9: 286
A10: Aurum Signature Studios | B10: 279
A11: Belatra Games | B11: 271
A12: Bet Games | B12: 61
A13: Betconstruct | B13: 34
... A133: Zeus Play | B133: 25

Sheet Data (Clean)
A1: Game ID | B1: Game | C1: Provider | D1: Provider ID | E1: Creator | F1: Creator ID | G1: Currency | H1: RM Bets | I1: RM Win | J1: GGR | K1: Bonus Bets | L1: Bonus Win | M1: Bonus Revenue | N1: Total Bets | O1: Total Win | P1: Payout | Q1: No. of Players | R1: First Bet | S1: Last Bet | T1: First Bet Clean | U1: Last Bet Clean | V1: First Bet Month | W1: Last Bet Month
A2: 421 | B2: All Fruits HD | C2: BetConstruct | D2: 2 | E2: Worldmatch | F2: 39 | G2: MYR | H2: 25 | I2: 0 | J2: 25 | K2: 0 | L2: 0 | M2: 0 | N2: 25 | O2: 0 | P2: 25 | Q2: 1 | R2: 2022-09-08T01:11:22+00:00 | S2: 2022-09-08T01:11:22+00:00 | T2: =LEFT(R2,10)&" "&MID(R2,12,8) -> 2022-09-08 01:11:22 | U2: =LEFT(S2,10)&" "&MID(S2,12,8) -> 2022-09-08 01:11:22 | V2: =VLOOKUP(MONTH(T2),Months!$A:$B,2,FALSE) -> September | W2: =VLOOKUP(MONTH(U2),Months!$A:$B,2,FALSE) -> September
A3: 697 | B3: Stoned Joker 5 | C3: BetConstruct | D3: 2 | E3: Fugaso | F3: 120 | G3: MYR | H3: 1568 | I3: 0 | J3: 1568 | K3: 0 | L3: 0 | M3: 0 | N3: 1568 | O3: 0 | P3: 1568 | Q3: 1 | R3: 2022-09-04T12:54:01+00:00 | S3: 2022-09-04T12:54:31+00:00 | T3: =LEFT(R3,10)&" "&MID(R3,12,8) -> 2022-09-04 12:54:01 | U3: =LEFT(S3,10)&" "&MID(S3,12,8) -> 2022-09-04 12:54:31 | V3: =VLOOKUP(MONTH(T3),Months!$A:$B,2,FALSE) -> September | W3: =VLOOKUP(MONTH(U3),Months!$A:$B,2,FALSE) -> September
A4: 1863 | B4: HotHoney 22 VIP | C4: BetConstruct | D4: 2 | E4: MrSlotty | F4: 45 | G4: MYR | H4: 125 | I4: 0 | J4: 125 | K4: 0 | L4: 0 | M4: 0 | N4: 125 | O4: 0 | P4: 125 | Q4: 1 | R4: 2022-09-07T11:34:38+00:00 | S4: 2022-09-07T11:34:38+00:00 | T4: =LEFT(R4,10)&" "&MID(R4,12,8) -> 2022-09-07 11:34:38 | U4: =LEFT(S4,10)&" "&MID(S4,12,8) -> 2022-09-07 11:34:38 | V4: =VLOOKUP(MONTH(T4),Months!$A:$B,2,FALSE) -> September | W4: =VLOOKUP(MONTH(U4),Months!$A:$B,2,FALSE) -> September
A5: 1871 | B5: Dolphins Gold | C5: BetConstruct | D5: 2 | E5: MrSlotty | F5: 45 | G5: MYR | H5: 20 | I5: 0 | J5: 20 | K5: 0 | L5: 0 | M5: 0 | N5: 20 | O5: 0 | P5: 20 | Q5: 1 | R5: 2022-08-17T18:44:45+00:00 | S5: 2022-07-17T18:44:58+00:00 | T5: =LEFT(R5,10)&" "&MID(R5,12,8) -> 2022-08-17 18:44:45 | U5: =LEFT(S5,10)&" "&MID(S5,12,8) -> 2022-07-17 18:44:58 | V5: =VLOOKUP(MONTH(T5),Months!$A:$B,2,FALSE) -> August | W5: =VLOOKUP(MONTH(U5),Months!$A:$B,2,FALSE) -> July
A6: 1908 | B6: Golfn Monkeys | C6: BetConstruct | D6: 2 | E6: Multislot | F6: 41 | G6: MYR | H6: 40 | I6: 0 | J6: 40 | K6: 0 | L6: 0 | M6: 0 | N6: 40 | O6: 0 | P6: 40 | Q6: 1 | R6: 2022-09-03T19:18:45+00:00 | S6: 2022-09-03T19:19:08+00:00 | T6: =LEFT(R6,10)&" "&MID(R6,12,8) -> 2022-09-03 19:18:45 | U6: =LEFT(S6,10)&" "&MID(S6,12,8) -> 2022-09-03 19:19:08 | V6: =VLOOKUP(MONTH(T6),Months!$A:$B,2,FALSE) -> September | W6: =VLOOKUP(MONTH(U6),Months!$A:$B,2,FALSE) -> September
A7: 2029 | B7: DragonTiger | C7: BetConstruct | D7: 2 | E7: AG Gaming | F7: 21 | G7: MYR | H7: 20000 | I7: 0 | J7: 20000 | K7: 0 | L7: 0 | M7: 0 | N7: 20000 | O7: 0 | P7: 20000 | Q7: 1 | R7: 2022-08-24T19:03:23+00:00 | S7: 2022-07-24T19:03:23+00:00 | T7: =LEFT(R7,10)&" "&MID(R7,12,8) -> 2022-08-24 19:03:23 | U7: =LEFT(S7,10)&" "&MID(S7,12,8) -> 2022-07-24 19:03:23 | V7: =VLOOKUP(MONTH(T7),Months!$A:$B,2,FALSE) -> August | W7: =VLOOKUP(MONTH(U7),Months!$A:$B,2,FALSE) -> July
A8: 2735 | B8: Roulette B | C8: BetConstruct | D8: 2 | E8: Betconstruct | F8: 34 | G8: MYR | H8: 5250 | I8: 0 | J8: 5250 | K8: 0 | L8: 0 | M8: 0 | N8: 5250 | O8: 0 | P8: 5250 | Q8: 1 | R8: 2022-08-29T09:46:12+00:00 | S8: 2022-08-29T09:49:10+00:00 | T8: =LEFT(R8,10)&" "&MID(R8,12,8) -> 2022-08-29 09:46:12 | U8: =LEFT(S8,10)&" "&MID(S8,12,8) -> 2022-08-29 09:49:10 | V8: =VLOOKUP(MONTH(T8),Months!$A:$B,2,FALSE) -> August | W8: =VLOOKUP(MONTH(U8),Months!$A:$B,2,FALSE) -> August
A9: 2750 | B9: Roulette | C9: BetConstruct | D9: 2 | E9: Vision Casino | F9: 161 | G9: MYR | H9: 450 | I9: 0 | J9: 450 | K9: 0 | L9: 0 | M9: 0 | N9: 450 | O9: 0 | P9: 450 | Q9: 1 | R9: 2022-08-22T05:09:33+00:00 | S9: 2022-08-22T05:09:33+00:00 | T9: =LEFT(R9,10)&" "&MID(R9,12,8) -> 2022-08-22 05:09:33 | U9: =LEFT(S9,10)&" "&MID(S9,12,8) -> 2022-08-22 05:09:33 | V9: =VLOOKUP(MONTH(T9),Months!$A:$B,2,FALSE) -> August | W9: =VLOOKUP(MONTH(U9),Months!$A:$B,2,FALSE) -> August
A10: 2767 | B10: Aztec Gems Deluxe™ | C10: BetConstruct | D10: 2 | E10: Pragmatic Play | F10: 24 | G10: MYR | H10: 72 | I10: 0 | J10: 72 | K10: 0 | L10: 0 | M10: 0 | N10: 72 | O10: 0 | P10: 72 | Q10: 1 | R10: 2022-08-07T04:42:22+00:00 | S10: 2022-07-07T04:42:25+00:00 | T10: =LEFT(R10,10)&" "&MID(R10,12,8) -> 2022-08-07 04:42:22 | U10: =LEFT(S10,10)&" "&MID(S10,12,8) -> 2022-07-07 04:42:25 | V10: =VLOOKUP(MONTH(T10),Months!$A:$B,2,FALSE) -> August | W10: =VLOOKUP(MONTH(U10),Months!$A:$B,2,FALSE) -> July
A11: 2879 | B11: Return of the Dead™ | C11: BetConstruct | D11: 2 | E11: Pragmatic Play | F11: 24 | G11: MYR | H11: 10000 | I11: 0 | J11: 10000 | K11: 0 | L11: 0 | M11: 0 | N11: 10000 | O11: 0 | P11: 10000 | Q11: 1 | R11: 2022-08-17T10:12:44+00:00 | S11: 2022-07-17T10:13:18+00:00 | T11: =LEFT(R11,10)&" "&MID(R11,12,8) -> 2022-08-17 10:12:44 | U11: =LEFT(S11,10)&" "&MID(S11,12,8) -> 2022-07-17 10:13:18 | V11: =VLOOKUP(MONTH(T11),Months!$A:$B,2,FALSE) -> August | W11: =VLOOKUP(MONTH(U11),Months!$A:$B,2,FALSE) -> July
A12: 3127 | B12: Aztec Temple | C12: Slotegrator | D12: 6 | E12: Platipus | F12: 249 | G12: MYR | H12: 300 | I12: 0 | J12: 300 | K12: 0 | L12: 0 | M12: 0 | N12: 300 | O12: 0 | P12: 300 | Q12: 1 | R12: 2022-08-20T17:37:57+00:00 | S12: 2022-07-20T17:38:03+00:00 | T12: =LEFT(R12,10)&" "&MID(R12,12,8) -> 2022-08-20 17:37:57 | U12: =LEFT(S12,10)&" "&MID(S12,12,8) -> 2022-07-20 17:38:03 | V12: =VLOOKUP(MONTH(T12),Months!$A:$B,2,FALSE) -> August | W12: =VLOOKUP(MONTH(U12),Months!$A:$B,2,FALSE) -> July
A13: 3174 | B13: Gladiator | C13: Slotegrator | D13: 6 | E13: Betsoft | F13: 55 | G13: MYR | H13: 50 | I13: 0 | J13: 50 | K13: 0 | L13: 0 | M13: 0 | N13: 50 | O13: 0 | P13: 50 | Q13: 1 | R13: 2022-08-29T18:44:47+00:00 | S13: 2022-08-29T18:44:56+00:00 | T13: =LEFT(R13,10)&" "&MID(R13,12,8) -> 2022-08-29 18:44:47 | U13: =LEFT(S13,10)&" "&MID(S13,12,8) -> 2022-08-29 18:44:56 | V13: =VLOOKUP(MONTH(T13),Months!$A:$B,2,FALSE) -> August | W13: =VLOOKUP(MONTH(U13),Months!$A:$B,2,FALSE) -> August
... A470: 20758 | B470: Amazing Link™ Bounty | C470: Mic | D470: 1 | E470: SpinPlay Games | F470: 156 | G470: MYR | H470: 10800 | I470: 2930 | J470: 7870 | K470: 0 | L470: 0 | M470: 0 | N470: 10800 | O470: 2930 | P470: 7870 | Q470: 1 | R470: 2022-08-16T07:28:12+00:00 | S470: 2022-08-16T07:33:44+00:00 | T470: =LEFT(R470,10)&" "&MID(R470,12,8) -> 2022-08-16 07:28:12 | U470: =LEFT(S470,10)&" "&MID(S470,12,8) -> 2022-08-16 07:33:44 | V470: =VLOOKUP(MONTH(T470),Months!$A:$B,2,FALSE) -> August | W470: =VLOOKUP(MONTH(U470),Months!$A:$B,2,FALSE) -> August
A471: 12868 | B471: 888 | C471: Slotegrator | D471: 6 | E471: Spadegaming | F471: 138 | G471: SGD | H471: 459843 | I471: 429760 | J471: 30083 | K471: 13417 | L471: 16300 | M471: -2883 | N471: 473260 | O471: 446060 | P471: 27200 | Q471: 25 | R471: 2022-07-02T14:25:09+00:00 | S471: 2022-09-28T01:43:01+00:00 | T471: =LEFT(R471,10)&" "&MID(R471,12,8) -> 2022-07-02 14:25:09 | U471: =LEFT(S471,10)&" "&MID(S471,12,8) -> 2022-09-28 01:43:01 | V471: =VLOOKUP(MONTH(T471),Months!$A:$B,2,FALSE) -> July | W471: =VLOOKUP(MONTH(U471),Months!$A:$B,2,FALSE) -> September
A472: 429 | B472: Legend of Ra | C472: BetConstruct | D472: 2 | E472: Evoplay Entertainment | F472: 116 | G472: SGD | H472: 220 | I472: 60 | J472: 160 | K472: 0 | L472: 0 | M472: 0 | N472: 220 | O472: 60 | P472: 160 | Q472: 1 | R472: 2022-08-23T03:15:18+00:00 | S472: 2022-07-23T03:16:15+00:00 | T472: =LEFT(R472,10)&" "&MID(R472,12,8) -> 2022-08-23 03:15:18 | U472: =LEFT(S472,10)&" "&MID(S472,12,8) -> 2022-07-23 03:16:15 | V472: =VLOOKUP(MONTH(T472),Months!$A:$B,2,FALSE) -> August | W472: =VLOOKUP(MONTH(U472),Months!$A:$B,2,FALSE) -> July
A473: 5814 | B473: Book Of Souls | C473: Mic | D473: 1 | E473: Spearhead Studios | F473: 154 | G473: SGD | H473: 4400 | I473: 1200 | J473: 3200 | K473: 0 | L473: 0 | M473: 0 | N473: 4400 | O473: 1200 | P473: 3200 | Q473: 1 | R473: 2022-09-19T03:54:26+00:00 | S473: 2022-09-19T03:59:00+00:00 | T473: =LEFT(R473,10)&" "&MID(R473,12,8) -> 2022-09-19 03:54:26 | U473: =LEFT(S473,10)&" "&MID(S473,12,8) -> 2022-09-19 03:59:00 | V473: =VLOOKUP(MONTH(T473),Months!$A:$B,2,FALSE) -> September | W473: =VLOOKUP(MONTH(U473),Months!$A:$B,2,FALSE) -> September
A474: 998 | B474: Five Star | C474: BetConstruct | D474: 2 | E474: Red Tiger | F474: 51 | G474: SGD | H474: 0 | I474: 0 | J474: 0 | K474: 3434 | L474: 937 | M474: 2497 | N474: 3434 | O474: 937 | P474: 2497 | Q474: 1 | R474: 2022-09-02T16:46:43+00:00 | S474: 2022-09-02T16:49:52+00:00 | T474: =LEFT(R474,10)&" "&MID(R474,12,8) -> 2022-09-02 16:46:43 | U474: =LEFT(S474,10)&" "&MID(S474,12,8) -> 2022-09-02 16:49:52 | V474: =VLOOKUP(MONTH(T474),Months!$A:$B,2,FALSE) -> September | W474: =VLOOKUP(MONTH(U474),Months!$A:$B,2,FALSE) -> September
A475: 3436 | B475: Sevens High Mobile | C475: Slotegrator | D475: 6 | E475: Quickspin | F475: 83 | G475: MYR | H475: 2775 | I475: 759 | J475: 2016 | K475: 0 | L475: 0 | M475: 0 | N475: 2775 | O475: 759 | P475: 2016 | Q475: 1 | R475: 2022-09-02T04:10:52+00:00 | S475: 2022-09-02T04:14:32+00:00 | T475: =LEFT(R475,10)&" "&MID(R475,12,8) -> 2022-09-02 04:10:52 | U475: =LEFT(S475,10)&" "&MID(S475,12,8) -> 2022-09-02 04:14:32 | V475: =VLOOKUP(MONTH(T475),Months!$A:$B,2,FALSE) -> September | W475: =VLOOKUP(MONTH(U475),Months!$A:$B,2,FALSE) -> September
A476: 16032 | B476: Star Pirates Code™ | C476: BetConstruct | D476: 2 | E476: Pragmatic Play | F476: 24 | G476: SGD | H476: 2550 | I476: 698 | J476: 1852 | K476: 0 | L476: 0 | M476: 0 | N476: 2550 | O476: 698 | P476: 1852 | Q476: 2 | R476: 2022-08-04T07:08:44+00:00 | S476: 2022-08-25T13:02:28+00:00 | T476: =LEFT(R476,10)&" "&MID(R476,12,8) -> 2022-08-04 07:08:44 | U476: =LEFT(S476,10)&" "&MID(S476,12,8) -> 2022-08-25 13:02:28 | V476: =VLOOKUP(MONTH(T476),Months!$A:$B,2,FALSE) -> August | W476: =VLOOKUP(MONTH(U476),Months!$A:$B,2,FALSE) -> August
A477: 17286 | B477: Tasty Treats | C477: Mic | D477: 1 | E477: Hacksaw Gamingsgsdgds | F477: 165 | G477: MYR | H477: 4480 | I477: 1228 | J477: 3252 | K477: 0 | L477: 0 | M477: 0 | N477: 4480 | O477: 1228 | P477: 3252 | Q477: 1 | R477: 2022-08-08T19:39:02+00:00 | S477: 2022-08-08T19:44:17+00:00 | T477: =LEFT(R477,10)&" "&MID(R477,12,8) -> 2022-08-08 19:39:02 | U477: =LEFT(S477,10)&" "&MID(S477,12,8) -> 2022-08-08 19:44:17 | V477: =VLOOKUP(MONTH(T477),Months!$A:$B,2,FALSE) -> August | W477: =VLOOKUP(MONTH(U477),Months!$A:$B,2,FALSE) -> August
A478: 982 | B478: Chinese Wilds | C478: BetConstruct | D478: 2 | E478: Red Tiger | F478: 51 | G478: SGD | H478: 1364 | I478: 374 | J478: 990 | K478: 0 | L478: 0 | M478: 0 | N478: 1364 | O478: 374 | P478: 990 | Q478: 4 | R478: 2022-08-10T22:59:29+00:00 | S478: 2022-09-15T07:54:48+00:00 | T478: =LEFT(R478,10)&" "&MID(R478,12,8) -> 2022-08-10 22:59:29 | U478: =LEFT(S478,10)&" "&MID(S478,12,8) -> 2022-09-15 07:54:48 | V478: =VLOOKUP(MONTH(T478),Months!$A:$B,2,FALSE) -> August | W478: =VLOOKUP(MONTH(U478),Months!$A:$B,2,FALSE) -> September
A479: 13260 | B479: Gems Bonanza Mobile | C479: Slotegrator | D479: 6 | E479: Pragmatic Play | F479: 24 | G479: MYR | H479: 160 | I479: 44 | J479: 116 | K479: 0 | L479: 0 | M479: 0 | N479: 160 | O479: 44 | P479: 116 | Q479: 1 | R479: 2022-09-28T12:29:54+00:00 | S479: 2022-09-28T12:30:26+00:00 | T479: =LEFT(R479,10)&" "&MID(R479,12,8) -> 2022-09-28 12:29:54 | U479: =LEFT(S479,10)&" "&MID(S479,12,8) -> 2022-09-28 12:30:26 | V479: =VLOOKUP(MONTH(T479),Months!$A:$B,2,FALSE) -> September | W479: =VLOOKUP(MONTH(U479),Months!$A:$B,2,FALSE) -> September
A480: 13651 | B480: Fast & Sexy | C480: BetConstruct | D480: 2 | E480: Genesis | F480: 27 | G480: SGD | H480: 1754 | I480: 483 | J480: 1271 | K480: 0 | L480: 0 | M480: 0 | N480: 1754 | O480: 483 | P480: 1271 | Q480: 1 | R480: 2022-09-25T09:30:45+00:00 | S480: 2022-09-25T09:31:31+00:00 | T480: =LEFT(R480,10)&" "&MID(R480,12,8) -> 2022-09-25 09:30:45 | U480: =LEFT(S480,10)&" "&MID(S480,12,8) -> 2022-09-25 09:31:31 | V480: =VLOOKUP(MONTH(T480),Months!$A:$B,2,FALSE) -> September | W480: =VLOOKUP(MONTH(U480),Months!$A:$B,2,FALSE) -> September
A481: 6436 | B481: Fortunium | C481: Mic | D481: 1 | E481: StormCraft | F481: 105 | G481: MYR | H481: 9450 | I481: 2610 | J481: 6840 | K481: 0 | L481: 0 | M481: 0 | N481: 9450 | O481: 2610 | P481: 6840 | Q481: 1 | R481: 2022-08-30T18:52:16+00:00 | S481: 2022-07-30T18:53:35+00:00 | T481: =LEFT(R481,10)&" "&MID(R481,12,8) -> 2022-08-30 18:52:16 | U481: =LEFT(S481,10)&" "&MID(S481,12,8) -> 2022-07-30 18:53:35 | V481: =VLOOKUP(MONTH(T481),Months!$A:$B,2,FALSE) -> August | W481: =VLOOKUP(MONTH(U481),Months!$A:$B,2,FALSE) -> July
A482: 1391 | B482: Emerald Diamond | C482: BetConstruct | D482: 2 | E482: Red Tiger | F482: 51 | G482: SGD | H482: 46937 | I482: 12963 | J482: 33974 | K482: 0 | L482: 0 | M482: 0 | N482: 46937 | O482: 12963 | P482: 33974 | Q482: 2 | R482: 2022-09-05T03:54:19+00:00 | S482: 2022-09-29T01:02:01+00:00 | T482: =LEFT(R482,10)&" "&MID(R482,12,8) -> 2022-09-05 03:54:19 | U482: =LEFT(S482,10)&" "&MID(S482,12,8) -> 2022-09-29 01:02:01 | V482: =VLOOKUP(MONTH(T482),Months!$A:$B,2,FALSE) -> September | W482: =VLOOKUP(MONTH(U482),Months!$A:$B,2,FALSE) -> September
A483: 5230 | B483: Money From Mars | C483: Mic | D483: 1 | E483: Ainsworth Games | F483: 80 | G483: MYR | H483: 6800 | I483: 1880 | J483: 4920 | K483: 0 | L483: 0 | M483: 0 | N483: 6800 | O483: 1880 | P483: 4920 | Q483: 1 | R483: 2022-08-29T16:10:00+00:00 | S483: 2022-08-29T16:12:00+00:00 | T483: =LEFT(R483,10)&" "&MID(R483,12,8) -> 2022-08-29 16:10:00 | U483: =LEFT(S483,10)&" "&MID(S483,12,8) -> 2022-08-29 16:12:00 | V483: =VLOOKUP(MONTH(T483),Months!$A:$B,2,FALSE) -> August | W483: =VLOOKUP(MONTH(U483),Months!$A:$B,2,FALSE) -> August
... A1083: 19593 | B1083: Divine Fire | C1083: BetConstruct | D1083: 2 | E1083: Gamomat | F1083: 164 | G1083: MYR | H1083: 10920 | I1083: 6020 | J1083: 4900 | K1083: 0 | L1083: 0 | M1083: 0 | N1083: 10920 | O1083: 6020 | P1083: 4900 | Q1083: 1 | R1083: 2022-09-03T05:17:35+00:00 | S1083: 2022-09-03T05:21:11+00:00 | T1083: =LEFT(R1083,10)&" "&MID(R1083,12,8) -> 2022-09-03 05:17:35 | U1083: =LEFT(S1083,10)&" "&MID(S1083,12,8) -> 2022-09-03 05:21:11 | V1083: =VLOOKUP(MONTH(T1083),Months!$A:$B,2,FALSE) -> September | W1083: =VLOOKUP(MONTH(U1083),Months!$A:$B,2,FALSE) -> September
A1084: 12868 | B1084: 888 | C1084: Slotegrator | D1084: 6 | E1084: Spadegaming | F1084: 138 | G1084: MYR | H1084: 580 | I1084: 320 | J1084: 260 | K1084: 0 | L1084: 0 | M1084: 0 | N1084: 580 | O1084: 320 | P1084: 260 | Q1084: 1 | R1084: 2022-09-20T04:24:09+00:00 | S1084: 2022-09-20T04:25:17+00:00 | T1084: =LEFT(R1084,10)&" "&MID(R1084,12,8) -> 2022-09-20 04:24:09 | U1084: =LEFT(S1084,10)&" "&MID(S1084,12,8) -> 2022-09-20 04:25:17 | V1084: =VLOOKUP(MONTH(T1084),Months!$A:$B,2,FALSE) -> September | W1084: =VLOOKUP(MONTH(U1084),Months!$A:$B,2,FALSE) -> September
A1085: 5642 | B1085: Barbarians Gold | C1085: Mic | D1085: 1 | E1085: 1x2 Gaming | F1085: 18 | G1085: MYR | H1085: 8940 | I1085: 4935 | J1085: 4005 | K1085: 0 | L1085: 0 | M1085: 0 | N1085: 8940 | O1085: 4935 | P1085: 4005 | Q1085: 1 | R1085: 2022-09-27T12:10:16+00:00 | S1085: 2022-09-27T12:18:01+00:00 | T1085: =LEFT(R1085,10)&" "&MID(R1085,12,8) -> 2022-09-27 12:10:16 | U1085: =LEFT(S1085,10)&" "&MID(S1085,12,8) -> 2022-09-27 12:18:01 | V1085: =VLOOKUP(MONTH(T1085),Months!$A:$B,2,FALSE) -> September | W1085: =VLOOKUP(MONTH(U1085),Months!$A:$B,2,FALSE) -> September
A1086: 17830 | B1086: Book of Amaterasu | C1086: Slotegrator | D1086: 6 | E1086: Mascot | F1086: 305 | G1086: MYR | H1086: 4600 | I1086: 2540 | J1086: 2060 | K1086: 0 | L1086: 0 | M1086: 0 | N1086: 4600 | O1086: 2540 | P1086: 2060 | Q1086: 1 | R1086: 2022-08-05T07:31:30+00:00 | S1086: 2022-08-05T07:32:54+00:00 | T1086: =LEFT(R1086,10)&" "&MID(R1086,12,8) -> 2022-08-05 07:31:30 | U1086: =LEFT(S1086,10)&" "&MID(S1086,12,8) -> 2022-08-05 07:32:54 | V1086: =VLOOKUP(MONTH(T1086),Months!$A:$B,2,FALSE) -> August | W1086: =VLOOKUP(MONTH(U1086),Months!$A:$B,2,FALSE) -> August
A1087: 13278 | B1087: The Dog House Mobile | C1087: Slotegrator | D1087: 6 | E1087: Pragmatic Play | F1087: 24 | G1087: SGD | H1087: 75380 | I1087: 118486 | J1087: -43106 | K1087: 3340 | L1087: 6802 | M1087: -3462 | N1087: 78720 | O1087: 125288 | P1087: -46568 | Q1087: 11 | R1087: 2022-09-28T15:11:56+00:00 | S1087: 2022-09-30T17:41:25+00:00 | T1087: =LEFT(R1087,10)&" "&MID(R1087,12,8) -> 2022-09-28 15:11:56 | U1087: =LEFT(S1087,10)&" "&MID(S1087,12,8) -> 2022-09-30 17:41:25 | V1087: =VLOOKUP(MONTH(T1087),Months!$A:$B,2,FALSE) -> September | W1087: =VLOOKUP(MONTH(U1087),Months!$A:$B,2,FALSE) -> September
A1088: 3336 | B1088: Pirate’s Charm | C1088: Slotegrator | D1088: 6 | E1088: Quickspin | F1088: 83 | G1088: MYR | H1088: 47040 | I1088: 25980 | J1088: 21060 | K1088: 0 | L1088: 0 | M1088: 0 | N1088: 47040 | O1088: 25980 | P1088: 21060 | Q1088: 2 | R1088: 2022-08-01T07:21:49+00:00 | S1088: 2022-09-30T14:17:43+00:00 | T1088: =LEFT(R1088,10)&" "&MID(R1088,12,8) -> 2022-08-01 07:21:49 | U1088: =LEFT(S1088,10)&" "&MID(S1088,12,8) -> 2022-09-30 14:17:43 | V1088: =VLOOKUP(MONTH(T1088),Months!$A:$B,2,FALSE) -> August | W1088: =VLOOKUP(MONTH(U1088),Months!$A:$B,2,FALSE) -> September
A1089: 987 | B1089: Divine Ways | C1089: BetConstruct | D1089: 2 | E1089: Red Tiger | F1089: 51 | G1089: SGD | H1089: 16935 | I1089: 9355 | J1089: 7580 | K1089: 0 | L1089: 0 | M1089: 0 | N1089: 16935 | O1089: 9355 | P1089: 7580 | Q1089: 7 | R1089: 2022-08-08T15:20:00+00:00 | S1089: 2022-09-17T16:16:29+00:00 | T1089: =LEFT(R1089,10)&" "&MID(R1089,12,8) -> 2022-08-08 15:20:00 | U1089: =LEFT(S1089,10)&" "&MID(S1089,12,8) -> 2022-09-17 16:16:29 | V1089: =VLOOKUP(MONTH(T1089),Months!$A:$B,2,FALSE) -> August | W1089: =VLOOKUP(MONTH(U1089),Months!$A:$B,2,FALSE) -> September
A1090: 12744 | B1090: El Paso Gunfight xNudge | C1090: BetConstruct | D1090: 2 | E1090: No LimitCity | F1090: 266 | G1090: MYR | H1090: 94250 | I1090: 52135 | J1090: 42115 | K1090: 0 | L1090: 0 | M1090: 0 | N1090: 94250 | O1090: 52135 | P1090: 42115 | Q1090: 5 | R1090: 2022-08-12T08:35:37+00:00 | S1090: 2022-08-31T00:16:22+00:00 | T1090: =LEFT(R1090,10)&" "&MID(R1090,12,8) -> 2022-08-12 08:35:37 | U1090: =LEFT(S1090,10)&" "&MID(S1090,12,8) -> 2022-08-31 00:16:22 | V1090: =VLOOKUP(MONTH(T1090),Months!$A:$B,2,FALSE) -> August | W1090: =VLOOKUP(MONTH(U1090),Months!$A:$B,2,FALSE) -> August
A1091: 6016 | B1091: Christmas Megaways | C1091: Mic | D1091: 1 | E1091: 1x2 Gaming | F1091: 18 | G1091: SGD | H1091: 8960 | I1091: 4958 | J1091: 4002 | K1091: 0 | L1091: 0 | M1091: 0 | N1091: 8960 | O1091: 4958 | P1091: 4002 | Q1091: 1 | R1091: 2022-08-31T06:36:34+00:00 | S1091: 2022-07-31T06:47:32+00:00 | T1091: =LEFT(R1091,10)&" "&MID(R1091,12,8) -> 2022-08-31 06:36:34 | U1091: =LEFT(S1091,10)&" "&MID(S1091,12,8) -> 2022-07-31 06:47:32 | V1091: =VLOOKUP(MONTH(T1091),Months!$A:$B,2,FALSE) -> August | W1091: =VLOOKUP(MONTH(U1091),Months!$A:$B,2,FALSE) -> July
A1092: 16074 | B1092: Wild Wet Win | C1092: Slotegrator | D1092: 6 | E1092: Spadegaming | F1092: 138 | G1092: SGD | H1092: 75204 | I1092: 47900 | J1092: 27304 | K1092: 22676 | L1092: 22595 | M1092: 81 | N1092: 97880 | O1092: 70495 | P1092: 27385 | Q1092: 11 | R1092: 2022-09-02T01:02:38+00:00 | S1092: 2022-09-30T23:59:30+00:00 | T1092: =LEFT(R1092,10)&" "&MID(R1092,12,8) -> 2022-09-02 01:02:38 | U1092: =LEFT(S1092,10)&" "&MID(S1092,12,8) -> 2022-09-30 23:59:30 | V1092: =VLOOKUP(MONTH(T1092),Months!$A:$B,2,FALSE) -> September | W1092: =VLOOKUP(MONTH(U1092),Months!$A:$B,2,FALSE) -> September
A1093: 20867 | B1093: Greedy Wolf™ | C1093: BetConstruct | D1093: 2 | E1093: Pragmatic Play | F1093: 24 | G1093: MYR | H1093: 210449 | I1093: 117165 | J1093: 93284 | K1093: 1221 | L1093: 354 | M1093: 867 | N1093: 211670 | O1093: 117519 | P1093: 94151 | Q1093: 5 | R1093: 2022-08-06T20:05:35+00:00 | S1093: 2022-09-14T13:51:48+00:00 | T1093: =LEFT(R1093,10)&" "&MID(R1093,12,8) -> 2022-08-06 20:05:35 | U1093: =LEFT(S1093,10)&" "&MID(S1093,12,8) -> 2022-09-14 13:51:48 | V1093: =VLOOKUP(MONTH(T1093),Months!$A:$B,2,FALSE) -> August | W1093: =VLOOKUP(MONTH(U1093),Months!$A:$B,2,FALSE) -> September
A1094: 11598 | B1094: Book Of Clovers | C1094: Slotegrator | D1094: 6 | E1094: SpinomenalFalse | F1094: 56 | G1094: SGD | H1094: 73857 | I1094: 37837 | J1094: 36020 | K1094: 2453 | L1094: 453 | M1094: 2000 | N1094: 76310 | O1094: 38290 | P1094: 38020 | Q1094: 15 | R1094: 2022-08-22T20:37:43+00:00 | S1094: 2022-09-28T11:56:18+00:00 | T1094: =LEFT(R1094,10)&" "&MID(R1094,12,8) -> 2022-08-22 20:37:43 | U1094: =LEFT(S1094,10)&" "&MID(S1094,12,8) -> 2022-09-28 11:56:18 | V1094: =VLOOKUP(MONTH(T1094),Months!$A:$B,2,FALSE) -> August | W1094: =VLOOKUP(MONTH(U1094),Months!$A:$B,2,FALSE) -> September
A1095: 12918 | B1095: Pirate King | C1095: Slotegrator | D1095: 6 | E1095: Spadegaming | F1095: 138 | G1095: SGD | H1095: 73548 | I1095: 56250 | J1095: 17298 | K1095: 0 | L1095: 0 | M1095: 0 | N1095: 73548 | O1095: 56250 | P1095: 17298 | Q1095: 2 | R1095: 2022-09-10T16:59:39+00:00 | S1095: 2022-09-20T06:53:02+00:00 | T1095: =LEFT(R1095,10)&" "&MID(R1095,12,8) -> 2022-09-10 16:59:39 | U1095: =LEFT(S1095,10)&" "&MID(S1095,12,8) -> 2022-09-20 06:53:02 | V1095: =VLOOKUP(MONTH(T1095),Months!$A:$B,2,FALSE) -> September | W1095: =VLOOKUP(MONTH(U1095),Months!$A:$B,2,FALSE) -> September
...

Sheet Popular Creators PT
A1: First Bet Month | B1: (All)
A2: Currency | B2: (All)
A4: Creator | B4: Total No. of Players
A5: 1x2 Gaming | B5: 18
A6: 2By2 | B6: 18
A7: AG Gaming | B7: 9
A8: Ainsworth Games | B8: 8
A9: Alchemy Gaming | B9: 3
A10: All41 Studios | B10: 4
A11: Amatic | B11: 1
A12: ASG | B12: 36
A13: Aurum Signature Studios | B13: 1
A14: Belatra Games | B14: 56
A15: Bet Games | B15: 48
A16: Betconstruct | B16: 13016
... A137: Grand Total | B137: 67947

Sheet Dashboard PTs
A1: First Bet Month | B1: September | D1: First Bet Month | E1: September | G1: First Bet Month | H1: September | K1: First Bet Month | L1: September
A3: Provider | B3: Total GGR | D3: Game | E3: Total GGR | G3: Game | H3: Total No. of Players | I3: Total GGR | K3: Creator | L3: Total GGR | O3: Column Labels
A4: BetConstruct | B4: 24251132 | D4: Mental | E4: 1338466 | G4: Royal Potato | H4: 348 | I4: 1871259 | K4: Pragmatic Play | L4: 7379156 | O4: Total | R4: Total No. of Players
A5: Slotegrator | B5: 9749701 | D5: Mega Ball | E5: 1389931 | G5: Mega Ball | H5: 314 | I5: 1389931 | K5: No LimitCity | L5: 7097431 | N5: Row Labels | O5: BetConstruct | P5: Mic | Q5: Slotegrator | R5: BetConstruct | S5: Mic | T5: Slotegrator
A6: Mic | B6: 5192157 | D6: Wanted Dead or a Wild | E6: 1456373 | G6: Money Train 3™ | H6: 279 | I6: 1061584 | K6: Relax Gaming | L6: 5307112 | N6: July | O6: 118613178 | P6: 604038 | Q6: 332114590 | R6: 28396 | S6: 854 | T6: 23351
A7: Grand Total | B7: 39192990 | D7: Fat Santa | E7: 1585931 | G7: Mental | H7: 225 | I7: 1338466 | K7: Hacksaw Gamingsgsdgds | L7: 3794256 | N7: August | O7: 17961911 | P7: 517231 | Q7: 3420950 | R7: 3248 | S7: 260 | T7: 1748
D8: Royal Potato | E8: 1871259 | G8: Tombstone | H8: 202 | I8: 486771 | K8: Evolution Gaming | L8: 2497928 | N8: September | O8: 24251132 | P8: 5192157 | Q8: 9749701 | R8: 6267 | S8: 783 | T8: 3040
D9: Grand Total | E9: 7641960 | G9: Grand Total | H9: 1368 | I9: 6148011 | K9: Push Gaming | L9: 2314358 | N9: Grand Total | O9: 160826221 | P9: 6313426 | Q9: 345285241 | R9: 37911 | S9: 1897 | T9: 28139
K10: Betconstruct | L10: 1704475
K11: Spadegaming | L11: 1274464
K12: Red Tiger | L12: 1270668
K13: SpinomenalFalse | L13: 951293
K14: Grand Total | L14: 33591141

Sheet Dashboard (September)

Sheet Months
A1: 1 | B1: January
A2: 2 | B2: February
A3: 3 | B3: March
A4: 4 | B4: April
A5: 5 | B5: May
A6: 6 | B6: June
A7: 7 | B7: July
A8: 8 | B8: August
A9: 9 | B9: September
A10: 10 | B10: October
A11: 11 | B11: November
A12: 12 | B12: December
